lob-alpha/data/raw/BTCUSDT_l2_sample.csv
timestamp,event_type,side,price,size
1700000000000000000,add,bid,29999.0,5.0
1700000000000000001,add,ask,30001.0,5.0
1700000000000000131,trade,ask,30001.0,0.9028
1700000000000000212,trade,ask,30001.0,0.8969
1700000000000000348,add,bid,29999.01,0.6772
1700000000000000473,trade,ask,30001.01,0.0843
1700000000000000550,trade,ask,30001.01,0.7423
1700000000000000671,trade,ask,30001.01,0.7974
1700000000000000790,trade,ask,30001.01,0.5666
1700000000000000875,add,bid,29999.02,0.0575
1700000000000000945,add,bid,29999.02,0.4413
1700000000000001014,trade,ask,30001.02,0.928
1700000000000001077,trade,ask,30001.02,0.1612
1700000000000001171,add,bid,29999.02,0.9782
1700000000000001314,trade,ask,30001.03,0.1936
1700000000000001412,trade,ask,30001.03,0.3872
1700000000000001542,add,bid,29999.03,1.041
1700000000000001665,trade,ask,30001.03,0.13
1700000000000001799,trade,ask,30001.03,0.3828
1700000000000001859,cancel,bid,29999.04,1.0465
1700000000000001957,trade,ask,30001.04,0.781
1700000000000002053,trade,ask,30001.04,0.4586
1700000000000002188,trade,ask,30001.04,1.1272
1700000000000002320,trade,ask,30001.04,0.7802
1700000000000002438,add,bid,29999.05,0.2379
1700000000000002536,trade,ask,30001.05,1.1142
1700000000000002674,trade,ask,30001.05,0.8373
1700000000000002822,add,bid,29999.05,0.3134
1700000000000002876,add,bid,29999.05,0.5113
1700000000000002934,trade,ask,30001.06,1.1343
1700000000000003075,trade,ask,30001.06,0.8038
1700000000000003175,cancel,bid,29999.06,0.7893
1700000000000003243,trade,ask,30001.06,0.3336
1700000000000003364,trade,ask,30001.06,0.9091
1700000000000003468,cancel,bid,29999.07,0.5093
1700000000000003546,cancel,bid,29999.07,0.2091
1700000000000003659,trade,ask,30001.07,0.1042
1700000000000003723,trade,ask,30001.07,0.234
1700000000000003860,trade,ask,30001.07,0.1231
1700000000000003958,trade,ask,30001.08,0.5883
1700000000000004040,cancel,bid,29999.08,1.0399
1700000000000004091,add,bid,29999.08,0.1817
1700000000000004209,add,bid,29999.08,0.9339
1700000000000004302,trade,ask,30001.08,0.55
1700000000000004410,trade,ask,30001.09,0.8804
1700000000000004552,trade,ask,30001.09,0.6257
1700000000000004624,trade,ask,30001.09,0.1724
1700000000000004754,trade,ask,30001.09,0.7848
1700000000000004881,trade,ask,30001.09,0.48
1700000000000004951,trade,ask,30001.1,0.9454
1700000000000005068,cancel,bid,29999.1,0.7388
1700000000000005180,trade,ask,30001.1,1.1185
1700000000000005269,trade,ask,30001.1,0.327
1700000000000005391,cancel,bid,29999.1,0.1485
1700000000000005503,add,bid,29999.11,1.1747
1700000000000005621,add,bid,29999.11,0.1977
1700000000000005731,cancel,bid,29999.11,0.2399
1700000000000005848,cancel,bid,29999.11,0.5366
1700000000000005925,cancel,bid,29999.11,0.9186
1700000000000006063,trade,ask,30001.12,0.4085
1700000000000006198,add,bid,29999.12,0.5538
1700000000000006314,trade,ask,30001.12,0.3351
1700000000000006372,trade,ask,30001.12,0.7266
1700000000000006451,trade,ask,30001.12,0.0583
1700000000000006591,add,bid,29999.13,0.3133
1700000000000006645,cancel,bid,29999.13,0.1315
1700000000000006725,trade,ask,30001.13,0.6082
1700000000000006844,trade,ask,30001.13,1.1258
1700000000000006967,trade,ask,30001.13,0.3294
1700000000000007077,add,bid,29999.14,0.269
1700000000000007139,add,bid,29999.14,0.4574
1700000000000007241,trade,ask,30001.14,0.8884
1700000000000007377,add,bid,29999.14,0.7931
1700000000000007434,trade,ask,30001.14,0.4402
1700000000000007497,trade,ask,30001.15,0.2687
1700000000000007604,trade,ask,30001.15,0.261
1700000000000007713,trade,ask,30001.15,1.1118
1700000000000007819,add,bid,29999.15,1.0344
1700000000000007881,trade,ask,30001.15,1.1992
1700000000000007932,cancel,bid,29999.16,1.1153
1700000000000008012,trade,ask,30001.16,0.6085
1700000000000008089,cancel,bid,29999.16,1.0878
1700000000000008160,trade,ask,30001.16,1.1831
1700000000000008243,cancel,bid,29999.16,0.9529
1700000000000008329,trade,ask,30001.17,1.1509
1700000000000008479,trade,ask,30001.17,0.8762
1700000000000008548,trade,ask,30001.17,0.3004
1700000000000008605,trade,ask,30001.17,0.6735
1700000000000008750,trade,ask,30001.17,0.1077
1700000000000008861,trade,ask,30001.18,1.0306
1700000000000008931,trade,ask,30001.18,0.634
1700000000000009004,trade,ask,30001.18,0.1282
1700000000000009084,trade,ask,30001.18,1.1328
1700000000000009206,trade,ask,30001.18,0.7337
1700000000000009335,trade,ask,30001.19,0.806
1700000000000009457,trade,ask,30001.19,1.1249
1700000000000009533,add,bid,29999.19,0.4113
1700000000000009616,trade,ask,30001.19,0.8224
1700000000000009704,trade,ask,30001.19,1.1184
1700000000000009763,trade,ask,30001.2,0.7643
1700000000000009885,cancel,bid,29999.2,0.1342
1700000000000009962,trade,ask,30001.2,0.2023
1700000000000010056,cancel,bid,29999.2,1.0612
1700000000000010153,trade,ask,30001.2,0.5539
1700000000000010272,add,bid,29999.21,0.7534
1700000000000010405,trade,ask,30001.21,0.818
1700000000000010525,trade,ask,30001.21,0.8129
1700000000000010592,trade,ask,30001.21,1.0732
1700000000000010737,trade,ask,30001.21,0.3632
1700000000000010864,trade,ask,30001.22,0.4443
1700000000000011001,add,bid,29999.22,0.3536
1700000000000011113,trade,ask,30001.22,1.0944
1700000000000011169,trade,ask,30001.22,0.5371
1700000000000011254,trade,ask,30001.22,0.4336
1700000000000011320,add,bid,29999.23,0.3512
1700000000000011464,trade,ask,30001.23,0.8615
1700000000000011585,trade,ask,30001.23,0.1365
1700000000000011723,cancel,bid,29999.23,0.6774
1700000000000011820,trade,ask,30001.23,0.2203
1700000000000011886,trade,ask,30001.24,0.4693
1700000000000011941,cancel,bid,29999.24,0.2916
1700000000000012022,add,bid,29999.24,0.4567
1700000000000012143,cancel,bid,29999.24,0.5173
1700000000000012272,add,bid,29999.24,1.1146
1700000000000012352,cancel,bid,29999.25,1.1726
1700000000000012424,cancel,bid,29999.25,0.0785
1700000000000012568,cancel,bid,29999.25,0.9497
1700000000000012670,add,bid,29999.25,1.0437
1700000000000012751,trade,ask,30001.25,0.9555
1700000000000012814,trade,ask,30001.26,0.0945
1700000000000012924,trade,ask,30001.26,0.9891
1700000000000013032,trade,ask,30001.26,0.9936
1700000000000013111,trade,ask,30001.26,0.809
1700000000000013212,trade,ask,30001.26,1.044
1700000000000013360,trade,ask,30001.27,0.7877
1700000000000013461,add,bid,29999.27,1.0202
1700000000000013553,cancel,bid,29999.27,0.1826
1700000000000013636,trade,ask,30001.27,1.1569
1700000000000013719,trade,ask,30001.27,0.7361
1700000000000013813,add,bid,29999.28,0.4107
1700000000000013940,cancel,bid,29999.28,0.183
1700000000000014063,trade,ask,30001.28,0.101
1700000000000014168,trade,ask,30001.28,1.1144
1700000000000014286,add,bid,29999.28,1.1313
1700000000000014430,add,bid,29999.29,0.4689
1700000000000014488,cancel,bid,29999.29,1.1089
1700000000000014617,trade,ask,30001.29,1.0252
1700000000000014759,cancel,bid,29999.29,0.6332
1700000000000014894,trade,ask,30001.29,0.5128
1700000000000014981,trade,ask,30001.3,0.2706
1700000000000015116,cancel,bid,29999.3,0.8289
1700000000000015188,add,bid,29999.3,0.3961
1700000000000015308,add,bid,29999.3,0.3995
1700000000000015384,trade,ask,30001.3,0.717
1700000000000015517,trade,ask,30001.31,0.5581
1700000000000015653,trade,ask,30001.31,0.5942
1700000000000015797,trade,ask,30001.31,0.1475
1700000000000015912,add,bid,29999.31,0.7621
1700000000000015973,add,bid,29999.31,0.9138
1700000000000016109,trade,ask,30001.32,0.9775
1700000000000016177,trade,ask,30001.32,0.3316
1700000000000016287,add,bid,29999.32,0.9338
1700000000000016395,trade,ask,30001.32,0.7742
1700000000000016469,add,bid,29999.32,0.4916
1700000000000016570,trade,ask,30001.33,0.8045
1700000000000016620,cancel,bid,29999.33,1.0395
1700000000000016683,add,bid,29999.33,0.3017
1700000000000016822,trade,ask,30001.33,0.1078
1700000000000016903,cancel,bid,29999.33,0.1896
1700000000000016970,add,bid,29999.34,0.8177
1700000000000017091,trade,ask,30001.34,1.1425
1700000000000017197,add,bid,29999.34,0.8772
